Workbook

Sheet Read me
A1: Project management software pricing, October 2026
A3: A snapshot of what fifteen project management tools charge, and a model that works out which tier you actually land on once you say how big your team is and what it needs.
A5: HOW TO USE IT
A6: Open the Inputs sheet and change the cells in blue on a yellow background. Nothing else is meant to be edited. Every other number recalculates from those.
A8: WHAT EACH SHEET IS
A9: Inputs the levers: team size, growth, billing cadence, and what the tool must do
A10: Model every tier scored against your inputs, with the reason any tier is ruled out
A11: Grid cost per month at six fixed team sizes, used by the comparison and the chart
A12: Compare the cheapest qualifying tier per vendor at each team size, and the chart
A13: Tiers the collected data, one row per vendor tier
A14: Bands vendors whose per-seat price falls as the team grows
A15: Add-ons capabilities sold separately rather than included in a tier
... A22: 3. Two vendors do not price by seat at all. Basecamp charges a flat fee and TeamGantt charges by project, so a per-seat comparison does not describe them. They are in the model where it is meaningful and excluded where it is not.

Sheet Inputs
A1: Inputs
A2: Edit the blue cells only. Everything else in the workbook follows from them.
A4: YOUR TEAM
A5: Seats today | B5: 25 | C5: How many people need a paid seat now.
A6: Annual growth in seats | B6: 0.2 | C6: Used to project seats over the horizon.
A7: Horizon, months | B7: 36 | C7: Length of the commitment you are costing.
A8: Billing cadence | B8: annual | C8: annual or monthly. Annual is cheaper everywhere in this data, by 14% to 37%.
A10: WHAT THE TOOL MUST DO
A11: Require SAML single sign-on | B11: no | C11: yes or no. Set yes and watch how few tiers survive.
A12: Require an audit log | B12: no | C12: yes or no.
A13: Require Gantt or timeline views | B13: no | C13: yes or no.
A15: Seats at the end of the horizon | B15: =ROUND(B5*(1+B6)^(B7/12),0) -> 43 | C15: Calculated, not an input.

Sheet Tiers
A1: Vendor | B1: Tier | C1: Order | D1: Pricing model | E1: Price per seat, annual | F1: Price per seat, monthly | G1: Flat price, annual | H1: Flat price, monthly | I1: Min seats | J1: Max seats | K1: Free tier | L1: Price visible | M1: SAML SSO | N1: Audit log | O1: Gantt or timeline | P1: Notes | Q1: Source | R1: Collected
A2: Smartsheet | B2: Pro | C2: 1 | D2: per_seat | E2: 9 | F2: 12 | I2: 1 | J2: 10 | K2: no | L2: public | M2: not_stated | N2: not_stated | O2: yes | P2: 1-10 Members, unlimited free Contributors | Q2: https://www.smartsheet.com/pricing | R2: 2026-10-02
A3: Smartsheet | B3: Business | C3: 2 | D3: per_seat | E3: 19 | F3: 24 | I3: 3 | K3: no | L3: public | M3: not_stated | N3: not_stated | O3: yes | P3: unlimited free Guests and Contributors | Q3: https://www.smartsheet.com/pricing | R3: 2026-10-02
A4: Smartsheet | B4: Enterprise | C4: 3 | D4: per_seat | I4: 10 | K4: no | L4: contact_sales | M4: yes | N4: not_stated | O4: yes | Q4: https://www.smartsheet.com/pricing | R4: 2026-10-02
A5: Smartsheet | B5: Advanced Work Management | C5: 4 | D5: per_seat | K5: no | L5: contact_sales | M5: yes | N5: not_stated | O5: yes | Q5: https://www.smartsheet.com/pricing | R5: 2026-10-02
A6: monday.com | B6: Free | C6: 0 | D6: per_seat | E6: 0 | F6: 0 | I6: 1 | J6: 2 | K6: yes | L6: public | M6: not_stated | N6: not_stated | O6: no | P6: up to 2 seats | Q6: https://monday.com/pricing | R6: 2026-10-02
A7: monday.com | B7: Basic | C7: 1 | D7: per_seat | E7: 9 | F7: 12 | K7: no | L7: public | M7: not_stated | N7: not_stated | O7: no | P7: AI credits billed separately: 1000 credits $10/mo, currently offset by a special monthly discount of -$10 | Q7: https://monday.com/pricing | R7: 2026-10-02
A8: monday.com | B8: Standard | C8: 2 | D8: per_seat | E8: 12 | F8: 14 | K8: no | L8: public | M8: not_stated | N8: not_stated | O8: yes | P8: 2000 AI credits $20/mo offset by -$20 promo; automations and integrations capped at 250 actions/month each; timeline and Gantt views start here | Q8: https://monday.com/pricing | R8: 2026-10-02
A9: monday.com | B9: Pro | C9: 3 | D9: per_seat | E9: 19 | F9: 24 | K9: no | L9: public | M9: not_stated | N9: not_stated | O9: yes | Q9: https://monday.com/pricing | R9: 2026-10-02
A10: monday.com | B10: Enterprise | C10: 4 | D10: per_seat | K10: no | L10: contact_sales | M10: not_stated | N10: not_stated | O10: yes | Q10: https://monday.com/pricing | R10: 2026-10-02
A11: ClickUp | B11: Free Forever | C11: 0 | D11: per_seat | E11: 0 | F11: 0 | I11: 1 | K11: yes | L11: public | M11: not_stated | N11: not_stated | O11: no | P11: 60MB storage, unlimited free plan members | Q11: https://clickup.com/pricing | R11: 2026-10-02
A12: ClickUp | B12: Unlimited | C12: 1 | D12: per_seat | E12: 7 | F12: 10 | I12: 1 | K12: no | L12: public | M12: not_stated | N12: not_stated | O12: yes | Q12: https://clickup.com/pricing | R12: 2026-10-02
A13: ClickUp | B13: Business | C13: 2 | D13: per_seat | E13: 12 | F13: 19 | I13: 1 | K13: no | L13: public | M13: not_stated | N13: not_stated | O13: yes | P13: 5K automations per month | Q13: https://clickup.com/pricing | R13: 2026-10-02
A14: ClickUp | B14: Enterprise | C14: 3 | D14: per_seat | K14: no | L14: contact_sales | M14: yes | N14: yes | O14: yes | P14: 250K automations per month | Q14: https://clickup.com/pricing | R14: 2026-10-02
A15: Trello | B15: Free | C15: 0 | D15: per_seat | E15: 0 | F15: 0 | I15: 1 | J15: 10 | K15: yes | L15: public | M15: not_stated | N15: not_stated | O15: no | P15: free for up to 10 collaborators per Workspace | Q15: https://trello.com/pricing | R15: 2026-10-02
A16: Trello | B16: Standard | C16: 1 | D16: per_seat | E16: 5 | F16: 6 | I16: 1 | K16: no | L16: public | M16: not_stated | N16: not_stated | O16: no | Q16: https://trello.com/pricing | R16: 2026-10-02
A17: Trello | B17: Premium | C17: 2 | D17: per_seat | E17: 10 | F17: 12.5 | I17: 1 | K17: no | L17: public | M17: not_stated | N17: not_stated | O17: yes | Q17: https://trello.com/pricing | R17: 2026-10-02
A18: Trello | B18: Enterprise | C18: 3 | D18: per_seat | E18: 17.5 | I18: 50 | K18: no | L18: public | M18: yes | N18: not_stated | O18: yes | P18: annual billing only; per-seat price falls with seat count, see volume_bands.csv; includes Atlassian Guard Standard | Q18: https://trello.com/pricing | R18: 2026-10-02
A19: Asana | B19: Personal | C19: 0 | D19: per_seat | E19: 0 | F19: 0 | I19: 1 | K19: yes | L19: public | M19: not_stated | N19: not_stated | O19: no | Q19: https://asana.com/pricing | R19: 2026-10-02
A20: Asana | B20: Starter | C20: 1 | D20: per_seat | E20: 10.99 | F20: 13.49 | I20: 1 | K20: no | L20: public | M20: not_stated | N20: not_stated | O20: yes | P20: unlimited free guests; timeline and Gantt views start here | Q20: https://asana.com/pricing | R20: 2026-10-02
A21: Asana | B21: Advanced | C21: 2 | D21: per_seat | E21: 24.99 | F21: 30.49 | I21: 1 | K21: no | L21: public | M21: not_stated | N21: not_stated | O21: yes | Q21: https://asana.com/pricing | R21: 2026-10-02
A22: Asana | B22: Enterprise | C22: 3 | D22: per_seat | K22: no | L22: contact_sales | M22: yes | N22: not_stated | O22: yes | P22: SAML authentication and SCIM user provisioning start here | Q22: https://asana.com/pricing | R22: 2026-10-02
A23: Notion | B23: Free | C23: 0 | D23: per_seat | E23: 0 | F23: 0 | I23: 1 | K23: yes | L23: public | M23: not_stated | N23: not_stated | O23: not_stated | Q23: https://www.notion.com/pricing | R23: 2026-10-02
A24: Notion | B24: Plus | C24: 1 | D24: per_seat | E24: 10 | F24: 12 | I24: 1 | K24: no | L24: public | M24: not_stated | N24: not_stated | O24: not_stated | Q24: https://www.notion.com/pricing | R24: 2026-10-02
A25: Notion | B25: Business | C25: 2 | D25: per_seat | E25: 20 | F25: 24 | I25: 1 | K25: no | L25: public | M25: yes | N25: not_stated | O25: not_stated | P25: SAML SSO starts here, not at Enterprise | Q25: https://www.notion.com/pricing | R25: 2026-10-02
A26: Notion | B26: Enterprise | C26: 3 | D26: per_seat | K26: no | L26: contact_sales | M26: yes | N26: yes | O26: not_stated | P26: audit log starts here | Q26: https://www.notion.com/pricing | R26: 2026-10-02
A27: Jira | B27: Free | C27: 0 | D27: per_seat | E27: 0 | F27: 0 | I27: 1 | K27: yes | L27: public | M27: not_stated | N27: not_stated | O27: not_stated | Q27: https://www.atlassian.com/software/jira/pricing | R27: 2026-10-02
A28: Jira | B28: Standard | C28: 1 | D28: per_seat | E28: 7.5 | F28: 9.05 | I28: 1 | K28: no | L28: public | M28: not_stated | N28: not_stated | O28: not_stated | P28: prices are the 1-100 user band; per-seat falls above 100 users, see volume_bands.csv | Q28: https://www.atlassian.com/software/jira/pricing | R28: 2026-10-02
A29: Jira | B29: Premium | C29: 2 | D29: per_seat | E29: 15.42 | F29: 18.3 | I29: 1 | K29: no | L29: public | M29: not_stated | N29: not_stated | O29: yes | P29: prices are the 1-100 user band | Q29: https://www.atlassian.com/software/jira/pricing | R29: 2026-10-02
A30: Jira | B30: Enterprise | C30: 3 | D30: per_seat | K30: no | L30: contact_sales | M30: not_stated | N30: not_stated | O30: yes | P30: annual billing only | Q30: https://www.atlassian.com/software/jira/pricing | R30: 2026-10-02
A31: Basecamp | B31: Free | C31: 0 | D31: flat | G31: 0 | H31: 0 | I31: 1 | J31: 5 | K31: yes | L31: public | M31: not_stated | N31: not_stated | O31: no | P31: 5 users max | Q31: https://basecamp.com/pricing | R31: 2026-10-02
A32: Basecamp | B32: Freelancer | C32: 1 | D32: flat | G32: 250 | H32: 25 | I32: 1 | J32: 20 | K32: no | L32: public | M32: not_stated | N32: not_stated | O32: no | P32: 20 users max, no per-user fees | Q32: https://basecamp.com/pricing | R32: 2026-10-02
A33: Basecamp | B33: Studio | C33: 2 | D33: flat | G33: 590 | H33: 59 | I33: 1 | K33: no | L33: public | M33: not_stated | N33: not_stated | O33: not_stated | P33: unlimited users, no per-user fees | Q33: https://basecamp.com/pricing | R33: 2026-10-02
A34: Basecamp | B34: Pro | C34: 3 | D34: flat | G34: 990 | H34: 99 | I34: 1 | K34: no | L34: public | M34: not_stated | N34: not_stated | O34: not_stated | P34: unlimited users, no per-user fees | Q34: https://basecamp.com/pricing | R34: 2026-10-02
A35: Basecamp | B35: Unlimited Edition | C35: 4 | D35: flat | G35: 3588 | H35: 299 | I35: 1 | K35: no | L35: public | M35: not_stated | N35: not_stated | O35: not_stated | P35: unlimited users, no per-user fees; billed annually | Q35: https://basecamp.com/pricing | R35: 2026-10-02
A36: Wrike | B36: Free | C36: 0 | D36: per_seat | E36: 0 | F36: 0 | I36: 1 | K36: yes | L36: public | M36: not_stated | N36: not_stated | O36: no | Q36: https://www.wrike.com/price/ | R36: 2026-10-02
A37: Wrike | B37: Team | C37: 1 | D37: per_seat | E37: 10 | I37: 2 | J37: 15 | K37: no | L37: public | M37: not_stated | N37: not_stated | O37: not_stated | P37: hard range 2 to 15 users; annual billing only on this page | Q37: https://www.wrike.com/price/ | R37: 2026-10-02
A38: Wrike | B38: Business | C38: 2 | D38: per_seat | E38: 25 | I38: 5 | J38: 200 | K38: no | L38: public | M38: not_stated | N38: not_stated | O38: yes | P38: hard range 5 to 200 users; a team under 5 still pays for 5 | Q38: https://www.wrike.com/price/ | R38: 2026-10-02
A39: Wrike | B39: Pinnacle | C39: 3 | D39: per_seat | K39: no | L39: contact_sales | M39: yes | N39: not_stated | O39: yes | Q39: https://www.wrike.com/price/ | R39: 2026-10-02
A40: Wrike | B40: Apex | C40: 4 | D40: per_seat | K40: no | L40: contact_sales | M40: yes | N40: not_stated | O40: yes | Q40: https://www.wrike.com/price/ | R40: 2026-10-02
...

Sheet Model
A1: Vendor | B1: Tier | C1: Seats billed | D1: Within seat cap | E1: Price published | F1: Meets requirements | G1: Qualifies | H1: Cost per month | I1: Cost over horizon | J1: Why it is ruled out
A2: =Tiers!A2 -> Smartsheet | B2: =Tiers!B2 -> Pro | C2: =MAX(Inputs!$B$5,IF(Tiers!I2="",1,Tiers!I2)) -> 25 | D2: =IF(Tiers!J2="",1,IF(Inputs!$B$5<=Tiers!J2,1,0)) -> 0 | E2: =IF(Tiers!L2="public",1,0) -> 1 | F2: =IF(AND(IF(Inputs!$B$11="yes",Tiers!M2="yes",TRUE()),IF(Inputs!$B$12="yes",Tiers!N2="yes",TRUE()),IF(Inputs!$B$13="yes",Tiers!O2="yes",TRUE())),1,0) -> 1 | G2: =IF(Tiers!K2="yes",0,D2*E2*F2) -> 0 | H2: =IF(G2=0,"",IF(Tiers!D2="per_seat", IF(Inputs!$B$8="annual",IF(Tiers!E2="","",Tiers!E2*C2), IF(Tiers!F2="","",Tiers!F2*C2)),IF(Tiers!D2="flat", IF(Inputs!$B$8="annual",IF(Tiers!G2="","",Tiers!G2/12), IF(Tiers!H2="","",Tiers!H2)),""))) | I2: =IF(H2="","",H2*Inputs!$B$7) | J2: =IF(Tiers!K2="yes","free tier, excluded from the paid comparison",IF(D2=0,"team is larger than this tier's seat cap",IF(E2=0,"no published price, contact sales",IF(F2=0,"does not meet a required capability",IF(H2="","not priced on the chosen billing cadence",""))))) -> team is larger than this tier's seat cap
A3: =Tiers!A3 -> Smartsheet | B3: =Tiers!B3 -> Business | C3: =MAX(Inputs!$B$5,IF(Tiers!I3="",1,Tiers!I3)) -> 25 | D3: =IF(Tiers!J3="",1,IF(Inputs!$B$5<=Tiers!J3,1,0)) -> 1 | E3: =IF(Tiers!L3="public",1,0) -> 1 | F3: =IF(AND(IF(Inputs!$B$11="yes",Tiers!M3="yes",TRUE()),IF(Inputs!$B$12="yes",Tiers!N3="yes",TRUE()),IF(Inputs!$B$13="yes",Tiers!O3="yes",TRUE())),1,0) -> 1 | G3: =IF(Tiers!K3="yes",0,D3*E3*F3) -> 1 | H3: =IF(G3=0,"",IF(Tiers!D3="per_seat", IF(Inputs!$B$8="annual",IF(Tiers!E3="","",Tiers!E3*C3), IF(Tiers!F3="","",Tiers!F3*C3)),IF(Tiers!D3="flat", IF(Inputs!$B$8="annual",IF(Tiers!G3="","",Tiers!G3/12), IF(Tiers!H3="","",Tiers!H3)),""))) -> 475 | I3: =IF(H3="","",H3*Inputs!$B$7) -> 17100 | J3: =IF(Tiers!K3="yes","free tier, excluded from the paid comparison",IF(D3=0,"team is larger than this tier's seat cap",IF(E3=0,"no published price, contact sales",IF(F3=0,"does not meet a required capability",IF(H3="","not priced on the chosen billing cadence","")))))
A4: =Tiers!A4 -> Smartsheet | B4: =Tiers!B4 -> Enterprise | C4: =MAX(Inputs!$B$5,IF(Tiers!I4="",1,Tiers!I4)) -> 25 | D4: =IF(Tiers!J4="",1,IF(Inputs!$B$5<=Tiers!J4,1,0)) -> 1 | E4: =IF(Tiers!L4="public",1,0) -> 0 | F4: =IF(AND(IF(Inputs!$B$11="yes",Tiers!M4="yes",TRUE()),IF(Inputs!$B$12="yes",Tiers!N4="yes",TRUE()),IF(Inputs!$B$13="yes",Tiers!O4="yes",TRUE())),1,0) -> 1 | G4: =IF(Tiers!K4="yes",0,D4*E4*F4) -> 0 | H4: =IF(G4=0,"",IF(Tiers!D4="per_seat", IF(Inputs!$B$8="annual",IF(Tiers!E4="","",Tiers!E4*C4), IF(Tiers!F4="","",Tiers!F4*C4)),IF(Tiers!D4="flat", IF(Inputs!$B$8="annual",IF(Tiers!G4="","",Tiers!G4/12), IF(Tiers!H4="","",Tiers!H4)),""))) | I4: =IF(H4="","",H4*Inputs!$B$7) | J4: =IF(Tiers!K4="yes","free tier, excluded from the paid comparison",IF(D4=0,"team is larger than this tier's seat cap",IF(E4=0,"no published price, contact sales",IF(F4=0,"does not meet a required capability",IF(H4="","not priced on the chosen billing cadence",""))))) -> no published price, contact sales
A5: =Tiers!A5 -> Smartsheet | B5: =Tiers!B5 -> Advanced Work Management | C5: =MAX(Inputs!$B$5,IF(Tiers!I5="",1,Tiers!I5)) -> 25 | D5: =IF(Tiers!J5="",1,IF(Inputs!$B$5<=Tiers!J5,1,0)) -> 1 | E5: =IF(Tiers!L5="public",1,0) -> 0 | F5: =IF(AND(IF(Inputs!$B$11="yes",Tiers!M5="yes",TRUE()),IF(Inputs!$B$12="yes",Tiers!N5="yes",TRUE()),IF(Inputs!$B$13="yes",Tiers!O5="yes",TRUE())),1,0) -> 1 | G5: =IF(Tiers!K5="yes",0,D5*E5*F5) -> 0 | H5: =IF(G5=0,"",IF(Tiers!D5="per_seat", IF(Inputs!$B$8="annual",IF(Tiers!E5="","",Tiers!E5*C5), IF(Tiers!F5="","",Tiers!F5*C5)),IF(Tiers!D5="flat", IF(Inputs!$B$8="annual",IF(Tiers!G5="","",Tiers!G5/12), IF(Tiers!H5="","",Tiers!H5)),""))) | I5: =IF(H5="","",H5*Inputs!$B$7) | J5: =IF(Tiers!K5="yes","free tier, excluded from the paid comparison",IF(D5=0,"team is larger than this tier's seat cap",IF(E5=0,"no published price, contact sales",IF(F5=0,"does not meet a required capability",IF(H5="","not priced on the chosen billing cadence",""))))) -> no published price, contact sales
A6: =Tiers!A6 -> monday.com | B6: =Tiers!B6 -> Free | C6: =MAX(Inputs!$B$5,IF(Tiers!I6="",1,Tiers!I6)) -> 25 | D6: =IF(Tiers!J6="",1,IF(Inputs!$B$5<=Tiers!J6,1,0)) -> 0 | E6: =IF(Tiers!L6="public",1,0) -> 1 | F6: =IF(AND(IF(Inputs!$B$11="yes",Tiers!M6="yes",TRUE()),IF(Inputs!$B$12="yes",Tiers!N6="yes",TRUE()),IF(Inputs!$B$13="yes",Tiers!O6="yes",TRUE())),1,0) -> 1 | G6: =IF(Tiers!K6="yes",0,D6*E6*F6) -> 0 | H6: =IF(G6=0,"",IF(Tiers!D6="per_seat", IF(Inputs!$B$8="annual",IF(Tiers!E6="","",Tiers!E6*C6), IF(Tiers!F6="","",Tiers!F6*C6)),IF(Tiers!D6="flat", IF(Inputs!$B$8="annual",IF(Tiers!G6="","",Tiers!G6/12), IF(Tiers!H6="","",Tiers!H6)),""))) | I6: =IF(H6="","",H6*Inputs!$B$7) | J6: =IF(Tiers!K6="yes","free tier, excluded from the paid comparison",IF(D6=0,"team is larger than this tier's seat cap",IF(E6=0,"no published price, contact sales",IF(F6=0,"does not meet a required capability",IF(H6="","not priced on the chosen billing cadence",""))))) -> free tier, excluded from the paid comparison
A7: =Tiers!A7 -> monday.com | B7: =Tiers!B7 -> Basic | C7: =MAX(Inputs!$B$5,IF(Tiers!I7="",1,Tiers!I7)) -> 25 | D7: =IF(Tiers!J7="",1,IF(Inputs!$B$5<=Tiers!J7,1,0)) -> 1 | E7: =IF(Tiers!L7="public",1,0) -> 1 | F7: =IF(AND(IF(Inputs!$B$11="yes",Tiers!M7="yes",TRUE()),IF(Inputs!$B$12="yes",Tiers!N7="yes",TRUE()),IF(Inputs!$B$13="yes",Tiers!O7="yes",TRUE())),1,0) -> 1 | G7: =IF(Tiers!K7="yes",0,D7*E7*F7) -> 1 | H7: =IF(G7=0,"",IF(Tiers!D7="per_seat", IF(Inputs!$B$8="annual",IF(Tiers!E7="","",Tiers!E7*C7), IF(Tiers!F7="","",Tiers!F7*C7)),IF(Tiers!D7="flat", IF(Inputs!$B$8="annual",IF(Tiers!G7="","",Tiers!G7/12), IF(Tiers!H7="","",Tiers!H7)),""))) -> 225 | I7: =IF(H7="","",H7*Inputs!$B$7) -> 8100 | J7: =IF(Tiers!K7="yes","free tier, excluded from the paid comparison",IF(D7=0,"team is larger than this tier's seat cap",IF(E7=0,"no published price, contact sales",IF(F7=0,"does not meet a required capability",IF(H7="","not priced on the chosen billing cadence","")))))
A8: =Tiers!A8 -> monday.com | B8: =Tiers!B8 -> Standard | C8: =MAX(Inputs!$B$5,IF(Tiers!I8="",1,Tiers!I8)) -> 25 | D8: =IF(Tiers!J8="",1,IF(Inputs!$B$5<=Tiers!J8,1,0)) -> 1 | E8: =IF(Tiers!L8="public",1,0) -> 1 | F8: =IF(AND(IF(Inputs!$B$11="yes",Tiers!M8="yes",TRUE()),IF(Inputs!$B$12="yes",Tiers!N8="yes",TRUE()),IF(Inputs!$B$13="yes",Tiers!O8="yes",TRUE())),1,0) -> 1 | G8: =IF(Tiers!K8="yes",0,D8*E8*F8) -> 1 | H8: =IF(G8=0,"",IF(Tiers!D8="per_seat", IF(Inputs!$B$8="annual",IF(Tiers!E8="","",Tiers!E8*C8), IF(Tiers!F8="","",Tiers!F8*C8)),IF(Tiers!D8="flat", IF(Inputs!$B$8="annual",IF(Tiers!G8="","",Tiers!G8/12), IF(Tiers!H8="","",Tiers!H8)),""))) -> 300 | I8: =IF(H8="","",H8*Inputs!$B$7) -> 10800 | J8: =IF(Tiers!K8="yes","free tier, excluded from the paid comparison",IF(D8=0,"team is larger than this tier's seat cap",IF(E8=0,"no published price, contact sales",IF(F8=0,"does not meet a required capability",IF(H8="","not priced on the chosen billing cadence","")))))
A9: =Tiers!A9 -> monday.com | B9: =Tiers!B9 -> Pro | C9: =MAX(Inputs!$B$5,IF(Tiers!I9="",1,Tiers!I9)) -> 25 | D9: =IF(Tiers!J9="",1,IF(Inputs!$B$5<=Tiers!J9,1,0)) -> 1 | E9: =IF(Tiers!L9="public",1,0) -> 1 | F9: =IF(AND(IF(Inputs!$B$11="yes",Tiers!M9="yes",TRUE()),IF(Inputs!$B$12="yes",Tiers!N9="yes",TRUE()),IF(Inputs!$B$13="yes",Tiers!O9="yes",TRUE())),1,0) -> 1 | G9: =IF(Tiers!K9="yes",0,D9*E9*F9) -> 1 | H9: =IF(G9=0,"",IF(Tiers!D9="per_seat", IF(Inputs!$B$8="annual",IF(Tiers!E9="","",Tiers!E9*C9), IF(Tiers!F9="","",Tiers!F9*C9)),IF(Tiers!D9="flat", IF(Inputs!$B$8="annual",IF(Tiers!G9="","",Tiers!G9/12), IF(Tiers!H9="","",Tiers!H9)),""))) -> 475 | I9: =IF(H9="","",H9*Inputs!$B$7) -> 17100 | J9: =IF(Tiers!K9="yes","free tier, excluded from the paid comparison",IF(D9=0,"team is larger than this tier's seat cap",IF(E9=0,"no published price, contact sales",IF(F9=0,"does not meet a required capability",IF(H9="","not priced on the chosen billing cadence","")))))
A10: =Tiers!A10 -> monday.com | B10: =Tiers!B10 -> Enterprise | C10: =MAX(Inputs!$B$5,IF(Tiers!I10="",1,Tiers!I10)) -> 25 | D10: =IF(Tiers!J10="",1,IF(Inputs!$B$5<=Tiers!J10,1,0)) -> 1 | E10: =IF(Tiers!L10="public",1,0) -> 0 | F10: =IF(AND(IF(Inputs!$B$11="yes",Tiers!M10="yes",TRUE()),IF(Inputs!$B$12="yes",Tiers!N10="yes",TRUE()),IF(Inputs!$B$13="yes",Tiers!O10="yes",TRUE())),1,0) -> 1 | G10: =IF(Tiers!K10="yes",0,D10*E10*F10) -> 0 | H10: =IF(G10=0,"",IF(Tiers!D10="per_seat", IF(Inputs!$B$8="annual",IF(Tiers!E10="","",Tiers!E10*C10), IF(Tiers!F10="","",Tiers!F10*C10)),IF(Tiers!D10="flat", IF(Inputs!$B$8="annual",IF(Tiers!G10="","",Tiers!G10/12), IF(Tiers!H10="","",Tiers!H10)),""))) | I10: =IF(H10="","",H10*Inputs!$B$7) | J10: =IF(Tiers!K10="yes","free tier, excluded from the paid comparison",IF(D10=0,"team is larger than this tier's seat cap",IF(E10=0,"no published price, contact sales",IF(F10=0,"does not meet a required capability",IF(H10="","not priced on the chosen billing cadence",""))))) -> no published price, contact sales
A11: =Tiers!A11 -> ClickUp | B11: =Tiers!B11 -> Free Forever | C11: =MAX(Inputs!$B$5,IF(Tiers!I11="",1,Tiers!I11)) -> 25 | D11: =IF(Tiers!J11="",1,IF(Inputs!$B$5<=Tiers!J11,1,0)) -> 1 | E11: =IF(Tiers!L11="public",1,0) -> 1 | F11: =IF(AND(IF(Inputs!$B$11="yes",Tiers!M11="yes",TRUE()),IF(Inputs!$B$12="yes",Tiers!N11="yes",TRUE()),IF(Inputs!$B$13="yes",Tiers!O11="yes",TRUE())),1,0) -> 1 | G11: =IF(Tiers!K11="yes",0,D11*E11*F11) -> 0 | H11: =IF(G11=0,"",IF(Tiers!D11="per_seat", IF(Inputs!$B$8="annual",IF(Tiers!E11="","",Tiers!E11*C11), IF(Tiers!F11="","",Tiers!F11*C11)),IF(Tiers!D11="flat", IF(Inputs!$B$8="annual",IF(Tiers!G11="","",Tiers!G11/12), IF(Tiers!H11="","",Tiers!H11)),""))) | I11: =IF(H11="","",H11*Inputs!$B$7) | J11: =IF(Tiers!K11="yes","free tier, excluded from the paid comparison",IF(D11=0,"team is larger than this tier's seat cap",IF(E11=0,"no published price, contact sales",IF(F11=0,"does not meet a required capability",IF(H11="","not priced on the chosen billing cadence",""))))) -> free tier, excluded from the paid comparison
A12: =Tiers!A12 -> ClickUp | B12: =Tiers!B12 -> Unlimited | C12: =MAX(Inputs!$B$5,IF(Tiers!I12="",1,Tiers!I12)) -> 25 | D12: =IF(Tiers!J12="",1,IF(Inputs!$B$5<=Tiers!J12,1,0)) -> 1 | E12: =IF(Tiers!L12="public",1,0) -> 1 | F12: =IF(AND(IF(Inputs!$B$11="yes",Tiers!M12="yes",TRUE()),IF(Inputs!$B$12="yes",Tiers!N12="yes",TRUE()),IF(Inputs!$B$13="yes",Tiers!O12="yes",TRUE())),1,0) -> 1 | G12: =IF(Tiers!K12="yes",0,D12*E12*F12) -> 1 | H12: =IF(G12=0,"",IF(Tiers!D12="per_seat", IF(Inputs!$B$8="annual",IF(Tiers!E12="","",Tiers!E12*C12), IF(Tiers!F12="","",Tiers!F12*C12)),IF(Tiers!D12="flat", IF(Inputs!$B$8="annual",IF(Tiers!G12="","",Tiers!G12/12), IF(Tiers!H12="","",Tiers!H12)),""))) -> 175 | I12: =IF(H12="","",H12*Inputs!$B$7) -> 6300 | J12: =IF(Tiers!K12="yes","free tier, excluded from the paid comparison",IF(D12=0,"team is larger than this tier's seat cap",IF(E12=0,"no published price, contact sales",IF(F12=0,"does not meet a required capability",IF(H12="","not priced on the chosen billing cadence","")))))
A13: =Tiers!A13 -> ClickUp | B13: =Tiers!B13 -> Business | C13: =MAX(Inputs!$B$5,IF(Tiers!I13="",1,Tiers!I13)) -> 25 | D13: =IF(Tiers!J13="",1,IF(Inputs!$B$5<=Tiers!J13,1,0)) -> 1 | E13: =IF(Tiers!L13="public",1,0) -> 1 | F13: =IF(AND(IF(Inputs!$B$11="yes",Tiers!M13="yes",TRUE()),IF(Inputs!$B$12="yes",Tiers!N13="yes",TRUE()),IF(Inputs!$B$13="yes",Tiers!O13="yes",TRUE())),1,0) -> 1 | G13: =IF(Tiers!K13="yes",0,D13*E13*F13) -> 1 | H13: =IF(G13=0,"",IF(Tiers!D13="per_seat", IF(Inputs!$B$8="annual",IF(Tiers!E13="","",Tiers!E13*C13), IF(Tiers!F13="","",Tiers!F13*C13)),IF(Tiers!D13="flat", IF(Inputs!$B$8="annual",IF(Tiers!G13="","",Tiers!G13/12), IF(Tiers!H13="","",Tiers!H13)),""))) -> 300 | I13: =IF(H13="","",H13*Inputs!$B$7) -> 10800 | J13: =IF(Tiers!K13="yes","free tier, excluded from the paid comparison",IF(D13=0,"team is larger than this tier's seat cap",IF(E13=0,"no published price, contact sales",IF(F13=0,"does not meet a required capability",IF(H13="","not priced on the chosen billing cadence","")))))
... A63: =Tiers!A63 -> Runrun.it | B63: =Tiers!B63 -> Enterprise | C63: =MAX(Inputs!$B$5,IF(Tiers!I63="",1,Tiers!I63)) -> 25 | D63: =IF(Tiers!J63="",1,IF(Inputs!$B$5<=Tiers!J63,1,0)) -> 1 | E63: =IF(Tiers!L63="public",1,0) -> 1 | F63: =IF(AND(IF(Inputs!$B$11="yes",Tiers!M63="yes",TRUE()),IF(Inputs!$B$12="yes",Tiers!N63="yes",TRUE()),IF(Inputs!$B$13="yes",Tiers!O63="yes",TRUE())),1,0) -> 1 | G63: =IF(Tiers!K63="yes",0,D63*E63*F63) -> 1 | H63: =IF(G63=0,"",IF(Tiers!D63="per_seat", IF(Inputs!$B$8="annual",IF(Tiers!E63="","",Tiers!E63*C63), IF(Tiers!F63="","",Tiers!F63*C63)),IF(Tiers!D63="flat", IF(Inputs!$B$8="annual",IF(Tiers!G63="","",Tiers!G63/12), IF(Tiers!H63="","",Tiers!H63)),""))) -> 650 | I63: =IF(H63="","",H63*Inputs!$B$7) -> 23400 | J63: =IF(Tiers!K63="yes","free tier, excluded from the paid comparison",IF(D63=0,"team is larger than this tier's seat cap",IF(E63=0,"no published price, contact sales",IF(F63=0,"does not meet a required capability",IF(H63="","not priced on the chosen billing cadence","")))))

Sheet Grid
A1: Cost per month at fixed team sizes
A2: Uses the capability requirements from Inputs but ignores the seat count there, so the comparison holds requirements fixed while team size varies.
A4: Vendor | B4: Tier | C4: 5 seats | D4: 10 seats | E4: 25 seats | F4: 50 seats | G4: 100 seats | H4: 250 seats
A5: =Tiers!A2 -> Smartsheet | B5: =Tiers!B2 -> Pro | C5: =IF(Tiers!K2="yes","",IF(Model!F2=0,"",IF(Tiers!L2<>"public","",IF(AND(Tiers!J2<>"",5>Tiers!J2),"",IF(Tiers!D2="per_seat", IF(Inputs!$B$8="annual",IF(Tiers!E2="","",Tiers!E2*MAX(5,IF(Tiers!I2="",1,Tiers!I2))), IF(Tiers!F2="","",Tiers!F2*MAX(5,IF(Tiers!I2="",1,Tiers!I2)))),IF(Tiers!D2="flat", IF(Inputs!$B$8="annual",IF(Tiers!G2="","",Tiers!G2/12), IF(Tiers!H2="","",Tiers!H2)),"")))))) -> 45 | D5: =IF(Tiers!K2="yes","",IF(Model!F2=0,"",IF(Tiers!L2<>"public","",IF(AND(Tiers!J2<>"",10>Tiers!J2),"",IF(Tiers!D2="per_seat", IF(Inputs!$B$8="annual",IF(Tiers!E2="","",Tiers!E2*MAX(10,IF(Tiers!I2="",1,Tiers!I2))), IF(Tiers!F2="","",Tiers!F2*MAX(10,IF(Tiers!I2="",1,Tiers!I2)))),IF(Tiers!D2="flat", IF(Inputs!$B$8="annual",IF(Tiers!G2="","",Tiers!G2/12), IF(Tiers!H2="","",Tiers!H2)),"")))))) -> 90 | E5: =IF(Tiers!K2="yes","",IF(Model!F2=0,"",IF(Tiers!L2<>"public","",IF(AND(Tiers!J2<>"",25>Tiers!J2),"",IF(Tiers!D2="per_seat", IF(Inputs!$B$8="annual",IF(Tiers!E2="","",Tiers!E2*MAX(25,IF(Tiers!I2="",1,Tiers!I2))), IF(Tiers!F2="","",Tiers!F2*MAX(25,IF(Tiers!I2="",1,Tiers!I2)))),IF(Tiers!D2="flat", IF(Inputs!$B$8="annual",IF(Tiers!G2="","",Tiers!G2/12), IF(Tiers!H2="","",Tiers!H2)),"")))))) | F5: =IF(Tiers!K2="yes","",IF(Model!F2=0,"",IF(Tiers!L2<>"public","",IF(AND(Tiers!J2<>"",50>Tiers!J2),"",IF(Tiers!D2="per_seat", IF(Inputs!$B$8="annual",IF(Tiers!E2="","",Tiers!E2*MAX(50,IF(Tiers!I2="",1,Tiers!I2))), IF(Tiers!F2="","",Tiers!F2*MAX(50,IF(Tiers!I2="",1,Tiers!I2)))),IF(Tiers!D2="flat", IF(Inputs!$B$8="annual",IF(Tiers!G2="","",Tiers!G2/12), IF(Tiers!H2="","",Tiers!H2)),"")))))) | G5: =IF(Tiers!K2="yes","",IF(Model!F2=0,"",IF(Tiers!L2<>"public","",IF(AND(Tiers!J2<>"",100>Tiers!J2),"",IF(Tiers!D2="per_seat", IF(Inputs!$B$8="annual",IF(Tiers!E2="","",Tiers!E2*MAX(100,IF(Tiers!I2="",1,Tiers!I2))), IF(Tiers!F2="","",Tiers!F2*MAX(100,IF(Tiers!I2="",1,Tiers!I2)))),IF(Tiers!D2="flat", IF(Inputs!$B$8="annual",IF(Tiers!G2="","",Tiers!G2/12), IF(Tiers!H2="","",Tiers!H2)),"")))))) | H5: =IF(Tiers!K2="yes","",IF(Model!F2=0,"",IF(Tiers!L2<>"public","",IF(AND(Tiers!J2<>"",250>Tiers!J2),"",IF(Tiers!D2="per_seat", IF(Inputs!$B$8="annual",IF(Tiers!E2="","",Tiers!E2*MAX(250,IF(Tiers!I2="",1,Tiers!I2))), IF(Tiers!F2="","",Tiers!F2*MAX(250,IF(Tiers!I2="",1,Tiers!I2)))),IF(Tiers!D2="flat", IF(Inputs!$B$8="annual",IF(Tiers!G2="","",Tiers!G2/12), IF(Tiers!H2="","",Tiers!H2)),""))))))
A6: =Tiers!A3 -> Smartsheet | B6: =Tiers!B3 -> Business | C6: =IF(Tiers!K3="yes","",IF(Model!F3=0,"",IF(Tiers!L3<>"public","",IF(AND(Tiers!J3<>"",5>Tiers!J3),"",IF(Tiers!D3="per_seat", IF(Inputs!$B$8="annual",IF(Tiers!E3="","",Tiers!E3*MAX(5,IF(Tiers!I3="",1,Tiers!I3))), IF(Tiers!F3="","",Tiers!F3*MAX(5,IF(Tiers!I3="",1,Tiers!I3)))),IF(Tiers!D3="flat", IF(Inputs!$B$8="annual",IF(Tiers!G3="","",Tiers!G3/12), IF(Tiers!H3="","",Tiers!H3)),"")))))) -> 95 | D6: =IF(Tiers!K3="yes","",IF(Model!F3=0,"",IF(Tiers!L3<>"public","",IF(AND(Tiers!J3<>"",10>Tiers!J3),"",IF(Tiers!D3="per_seat", IF(Inputs!$B$8="annual",IF(Tiers!E3="","",Tiers!E3*MAX(10,IF(Tiers!I3="",1,Tiers!I3))), IF(Tiers!F3="","",Tiers!F3*MAX(10,IF(Tiers!I3="",1,Tiers!I3)))),IF(Tiers!D3="flat", IF(Inputs!$B$8="annual",IF(Tiers!G3="","",Tiers!G3/12), IF(Tiers!H3="","",Tiers!H3)),"")))))) -> 190 | E6: =IF(Tiers!K3="yes","",IF(Model!F3=0,"",IF(Tiers!L3<>"public","",IF(AND(Tiers!J3<>"",25>Tiers!J3),"",IF(Tiers!D3="per_seat", IF(Inputs!$B$8="annual",IF(Tiers!E3="","",Tiers!E3*MAX(25,IF(Tiers!I3="",1,Tiers!I3))), IF(Tiers!F3="","",Tiers!F3*MAX(25,IF(Tiers!I3="",1,Tiers!I3)))),IF(Tiers!D3="flat", IF(Inputs!$B$8="annual",IF(Tiers!G3="","",Tiers!G3/12), IF(Tiers!H3="","",Tiers!H3)),"")))))) -> 475 | F6: =IF(Tiers!K3="yes","",IF(Model!F3=0,"",IF(Tiers!L3<>"public","",IF(AND(Tiers!J3<>"",50>Tiers!J3),"",IF(Tiers!D3="per_seat", IF(Inputs!$B$8="annual",IF(Tiers!E3="","",Tiers!E3*MAX(50,IF(Tiers!I3="",1,Tiers!I3))), IF(Tiers!F3="","",Tiers!F3*MAX(50,IF(Tiers!I3="",1,Tiers!I3)))),IF(Tiers!D3="flat", IF(Inputs!$B$8="annual",IF(Tiers!G3="","",Tiers!G3/12), IF(Tiers!H3="","",Tiers!H3)),"")))))) -> 950 | G6: =IF(Tiers!K3="yes","",IF(Model!F3=0,"",IF(Tiers!L3<>"public","",IF(AND(Tiers!J3<>"",100>Tiers!J3),"",IF(Tiers!D3="per_seat", IF(Inputs!$B$8="annual",IF(Tiers!E3="","",Tiers!E3*MAX(100,IF(Tiers!I3="",1,Tiers!I3))), IF(Tiers!F3="","",Tiers!F3*MAX(100,IF(Tiers!I3="",1,Tiers!I3)))),IF(Tiers!D3="flat", IF(Inputs!$B$8="annual",IF(Tiers!G3="","",Tiers!G3/12), IF(Tiers!H3="","",Tiers!H3)),"")))))) -> 1900 | H6: =IF(Tiers!K3="yes","",IF(Model!F3=0,"",IF(Tiers!L3<>"public","",IF(AND(Tiers!J3<>"",250>Tiers!J3),"",IF(Tiers!D3="per_seat", IF(Inputs!$B$8="annual",IF(Tiers!E3="","",Tiers!E3*MAX(250,IF(Tiers!I3="",1,Tiers!I3))), IF(Tiers!F3="","",Tiers!F3*MAX(250,IF(Tiers!I3="",1,Tiers!I3)))),IF(Tiers!D3="flat", IF(Inputs!$B$8="annual",IF(Tiers!G3="","",Tiers!G3/12), IF(Tiers!H3="","",Tiers!H3)),"")))))) -> 4750
A7: =Tiers!A4 -> Smartsheet | B7: =Tiers!B4 -> Enterprise | C7: =IF(Tiers!K4="yes","",IF(Model!F4=0,"",IF(Tiers!L4<>"public","",IF(AND(Tiers!J4<>"",5>Tiers!J4),"",IF(Tiers!D4="per_seat", IF(Inputs!$B$8="annual",IF(Tiers!E4="","",Tiers!E4*MAX(5,IF(Tiers!I4="",1,Tiers!I4))), IF(Tiers!F4="","",Tiers!F4*MAX(5,IF(Tiers!I4="",1,Tiers!I4)))),IF(Tiers!D4="flat", IF(Inputs!$B$8="annual",IF(Tiers!G4="","",Tiers!G4/12), IF(Tiers!H4="","",Tiers!H4)),"")))))) | D7: =IF(Tiers!K4="yes","",IF(Model!F4=0,"",IF(Tiers!L4<>"public","",IF(AND(Tiers!J4<>"",10>Tiers!J4),"",IF(Tiers!D4="per_seat", IF(Inputs!$B$8="annual",IF(Tiers!E4="","",Tiers!E4*MAX(10,IF(Tiers!I4="",1,Tiers!I4))), IF(Tiers!F4="","",Tiers!F4*MAX(10,IF(Tiers!I4="",1,Tiers!I4)))),IF(Tiers!D4="flat", IF(Inputs!$B$8="annual",IF(Tiers!G4="","",Tiers!G4/12), IF(Tiers!H4="","",Tiers!H4)),"")))))) | E7: =IF(Tiers!K4="yes","",IF(Model!F4=0,"",IF(Tiers!L4<>"public","",IF(AND(Tiers!J4<>"",25>Tiers!J4),"",IF(Tiers!D4="per_seat", IF(Inputs!$B$8="annual",IF(Tiers!E4="","",Tiers!E4*MAX(25,IF(Tiers!I4="",1,Tiers!I4))), IF(Tiers!F4="","",Tiers!F4*MAX(25,IF(Tiers!I4="",1,Tiers!I4)))),IF(Tiers!D4="flat", IF(Inputs!$B$8="annual",IF(Tiers!G4="","",Tiers!G4/12), IF(Tiers!H4="","",Tiers!H4)),"")))))) | F7: =IF(Tiers!K4="yes","",IF(Model!F4=0,"",IF(Tiers!L4<>"public","",IF(AND(Tiers!J4<>"",50>Tiers!J4),"",IF(Tiers!D4="per_seat", IF(Inputs!$B$8="annual",IF(Tiers!E4="","",Tiers!E4*MAX(50,IF(Tiers!I4="",1,Tiers!I4))), IF(Tiers!F4="","",Tiers!F4*MAX(50,IF(Tiers!I4="",1,Tiers!I4)))),IF(Tiers!D4="flat", IF(Inputs!$B$8="annual",IF(Tiers!G4="","",Tiers!G4/12), IF(Tiers!H4="","",Tiers!H4)),"")))))) | G7: =IF(Tiers!K4="yes","",IF(Model!F4=0,"",IF(Tiers!L4<>"public","",IF(AND(Tiers!J4<>"",100>Tiers!J4),"",IF(Tiers!D4="per_seat", IF(Inputs!$B$8="annual",IF(Tiers!E4="","",Tiers!E4*MAX(100,IF(Tiers!I4="",1,Tiers!I4))), IF(Tiers!F4="","",Tiers!F4*MAX(100,IF(Tiers!I4="",1,Tiers!I4)))),IF(Tiers!D4="flat", IF(Inputs!$B$8="annual",IF(Tiers!G4="","",Tiers!G4/12), IF(Tiers!H4="","",Tiers!H4)),"")))))) | H7: =IF(Tiers!K4="yes","",IF(Model!F4=0,"",IF(Tiers!L4<>"public","",IF(AND(Tiers!J4<>"",250>Tiers!J4),"",IF(Tiers!D4="per_seat", IF(Inputs!$B$8="annual",IF(Tiers!E4="","",Tiers!E4*MAX(250,IF(Tiers!I4="",1,Tiers!I4))), IF(Tiers!F4="","",Tiers!F4*MAX(250,IF(Tiers!I4="",1,Tiers!I4)))),IF(Tiers!D4="flat", IF(Inputs!$B$8="annual",IF(Tiers!G4="","",Tiers!G4/12), IF(Tiers!H4="","",Tiers!H4)),""))))))
A8: =Tiers!A5 -> Smartsheet | B8: =Tiers!B5 -> Advanced Work Management | C8: =IF(Tiers!K5="yes","",IF(Model!F5=0,"",IF(Tiers!L5<>"public","",IF(AND(Tiers!J5<>"",5>Tiers!J5),"",IF(Tiers!D5="per_seat", IF(Inputs!$B$8="annual",IF(Tiers!E5="","",Tiers!E5*MAX(5,IF(Tiers!I5="",1,Tiers!I5))), IF(Tiers!F5="","",Tiers!F5*MAX(5,IF(Tiers!I5="",1,Tiers!I5)))),IF(Tiers!D5="flat", IF(Inputs!$B$8="annual",IF(Tiers!G5="","",Tiers!G5/12), IF(Tiers!H5="","",Tiers!H5)),"")))))) | D8: =IF(Tiers!K5="yes","",IF(Model!F5=0,"",IF(Tiers!L5<>"public","",IF(AND(Tiers!J5<>"",10>Tiers!J5),"",IF(Tiers!D5="per_seat", IF(Inputs!$B$8="annual",IF(Tiers!E5="","",Tiers!E5*MAX(10,IF(Tiers!I5="",1,Tiers!I5))), IF(Tiers!F5="","",Tiers!F5*MAX(10,IF(Tiers!I5="",1,Tiers!I5)))),IF(Tiers!D5="flat", IF(Inputs!$B$8="annual",IF(Tiers!G5="","",Tiers!G5/12), IF(Tiers!H5="","",Tiers!H5)),"")))))) | E8: =IF(Tiers!K5="yes","",IF(Model!F5=0,"",IF(Tiers!L5<>"public","",IF(AND(Tiers!J5<>"",25>Tiers!J5),"",IF(Tiers!D5="per_seat", IF(Inputs!$B$8="annual",IF(Tiers!E5="","",Tiers!E5*MAX(25,IF(Tiers!I5="",1,Tiers!I5))), IF(Tiers!F5="","",Tiers!F5*MAX(25,IF(Tiers!I5="",1,Tiers!I5)))),IF(Tiers!D5="flat", IF(Inputs!$B$8="annual",IF(Tiers!G5="","",Tiers!G5/12), IF(Tiers!H5="","",Tiers!H5)),"")))))) | F8: =IF(Tiers!K5="yes","",IF(Model!F5=0,"",IF(Tiers!L5<>"public","",IF(AND(Tiers!J5<>"",50>Tiers!J5),"",IF(Tiers!D5="per_seat", IF(Inputs!$B$8="annual",IF(Tiers!E5="","",Tiers!E5*MAX(50,IF(Tiers!I5="",1,Tiers!I5))), IF(Tiers!F5="","",Tiers!F5*MAX(50,IF(Tiers!I5="",1,Tiers!I5)))),IF(Tiers!D5="flat", IF(Inputs!$B$8="annual",IF(Tiers!G5="","",Tiers!G5/12), IF(Tiers!H5="","",Tiers!H5)),"")))))) | G8: =IF(Tiers!K5="yes","",IF(Model!F5=0,"",IF(Tiers!L5<>"public","",IF(AND(Tiers!J5<>"",100>Tiers!J5),"",IF(Tiers!D5="per_seat", IF(Inputs!$B$8="annual",IF(Tiers!E5="","",Tiers!E5*MAX(100,IF(Tiers!I5="",1,Tiers!I5))), IF(Tiers!F5="","",Tiers!F5*MAX(100,IF(Tiers!I5="",1,Tiers!I5)))),IF(Tiers!D5="flat", IF(Inputs!$B$8="annual",IF(Tiers!G5="","",Tiers!G5/12), IF(Tiers!H5="","",Tiers!H5)),"")))))) | H8: =IF(Tiers!K5="yes","",IF(Model!F5=0,"",IF(Tiers!L5<>"public","",IF(AND(Tiers!J5<>"",250>Tiers!J5),"",IF(Tiers!D5="per_seat", IF(Inputs!$B$8="annual",IF(Tiers!E5="","",Tiers!E5*MAX(250,IF(Tiers!I5="",1,Tiers!I5))), IF(Tiers!F5="","",Tiers!F5*MAX(250,IF(Tiers!I5="",1,Tiers!I5)))),IF(Tiers!D5="flat", IF(Inputs!$B$8="annual",IF(Tiers!G5="","",Tiers!G5/12), IF(Tiers!H5="","",Tiers!H5)),""))))))
A9: =Tiers!A6 -> monday.com | B9: =Tiers!B6 -> Free | C9: =IF(Tiers!K6="yes","",IF(Model!F6=0,"",IF(Tiers!L6<>"public","",IF(AND(Tiers!J6<>"",5>Tiers!J6),"",IF(Tiers!D6="per_seat", IF(Inputs!$B$8="annual",IF(Tiers!E6="","",Tiers!E6*MAX(5,IF(Tiers!I6="",1,Tiers!I6))), IF(Tiers!F6="","",Tiers!F6*MAX(5,IF(Tiers!I6="",1,Tiers!I6)))),IF(Tiers!D6="flat", IF(Inputs!$B$8="annual",IF(Tiers!G6="","",Tiers!G6/12), IF(Tiers!H6="","",Tiers!H6)),"")))))) | D9: =IF(Tiers!K6="yes","",IF(Model!F6=0,"",IF(Tiers!L6<>"public","",IF(AND(Tiers!J6<>"",10>Tiers!J6),"",IF(Tiers!D6="per_seat", IF(Inputs!$B$8="annual",IF(Tiers!E6="","",Tiers!E6*MAX(10,IF(Tiers!I6="",1,Tiers!I6))), IF(Tiers!F6="","",Tiers!F6*MAX(10,IF(Tiers!I6="",1,Tiers!I6)))),IF(Tiers!D6="flat", IF(Inputs!$B$8="annual",IF(Tiers!G6="","",Tiers!G6/12), IF(Tiers!H6="","",Tiers!H6)),"")))))) | E9: =IF(Tiers!K6="yes","",IF(Model!F6=0,"",IF(Tiers!L6<>"public","",IF(AND(Tiers!J6<>"",25>Tiers!J6),"",IF(Tiers!D6="per_seat", IF(Inputs!$B$8="annual",IF(Tiers!E6="","",Tiers!E6*MAX(25,IF(Tiers!I6="",1,Tiers!I6))), IF(Tiers!F6="","",Tiers!F6*MAX(25,IF(Tiers!I6="",1,Tiers!I6)))),IF(Tiers!D6="flat", IF(Inputs!$B$8="annual",IF(Tiers!G6="","",Tiers!G6/12), IF(Tiers!H6="","",Tiers!H6)),"")))))) | F9: =IF(Tiers!K6="yes","",IF(Model!F6=0,"",IF(Tiers!L6<>"public","",IF(AND(Tiers!J6<>"",50>Tiers!J6),"",IF(Tiers!D6="per_seat", IF(Inputs!$B$8="annual",IF(Tiers!E6="","",Tiers!E6*MAX(50,IF(Tiers!I6="",1,Tiers!I6))), IF(Tiers!F6="","",Tiers!F6*MAX(50,IF(Tiers!I6="",1,Tiers!I6)))),IF(Tiers!D6="flat", IF(Inputs!$B$8="annual",IF(Tiers!G6="","",Tiers!G6/12), IF(Tiers!H6="","",Tiers!H6)),"")))))) | G9: =IF(Tiers!K6="yes","",IF(Model!F6=0,"",IF(Tiers!L6<>"public","",IF(AND(Tiers!J6<>"",100>Tiers!J6),"",IF(Tiers!D6="per_seat", IF(Inputs!$B$8="annual",IF(Tiers!E6="","",Tiers!E6*MAX(100,IF(Tiers!I6="",1,Tiers!I6))), IF(Tiers!F6="","",Tiers!F6*MAX(100,IF(Tiers!I6="",1,Tiers!I6)))),IF(Tiers!D6="flat", IF(Inputs!$B$8="annual",IF(Tiers!G6="","",Tiers!G6/12), IF(Tiers!H6="","",Tiers!H6)),"")))))) | H9: =IF(Tiers!K6="yes","",IF(Model!F6=0,"",IF(Tiers!L6<>"public","",IF(AND(Tiers!J6<>"",250>Tiers!J6),"",IF(Tiers!D6="per_seat", IF(Inputs!$B$8="annual",IF(Tiers!E6="","",Tiers!E6*MAX(250,IF(Tiers!I6="",1,Tiers!I6))), IF(Tiers!F6="","",Tiers!F6*MAX(250,IF(Tiers!I6="",1,Tiers!I6)))),IF(Tiers!D6="flat", IF(Inputs!$B$8="annual",IF(Tiers!G6="","",Tiers!G6/12), IF(Tiers!H6="","",Tiers!H6)),""))))))
A10: =Tiers!A7 -> monday.com | B10: =Tiers!B7 -> Basic | C10: =IF(Tiers!K7="yes","",IF(Model!F7=0,"",IF(Tiers!L7<>"public","",IF(AND(Tiers!J7<>"",5>Tiers!J7),"",IF(Tiers!D7="per_seat", IF(Inputs!$B$8="annual",IF(Tiers!E7="","",Tiers!E7*MAX(5,IF(Tiers!I7="",1,Tiers!I7))), IF(Tiers!F7="","",Tiers!F7*MAX(5,IF(Tiers!I7="",1,Tiers!I7)))),IF(Tiers!D7="flat", IF(Inputs!$B$8="annual",IF(Tiers!G7="","",Tiers!G7/12), IF(Tiers!H7="","",Tiers!H7)),"")))))) -> 45 | D10: =IF(Tiers!K7="yes","",IF(Model!F7=0,"",IF(Tiers!L7<>"public","",IF(AND(Tiers!J7<>"",10>Tiers!J7),"",IF(Tiers!D7="per_seat", IF(Inputs!$B$8="annual",IF(Tiers!E7="","",Tiers!E7*MAX(10,IF(Tiers!I7="",1,Tiers!I7))), IF(Tiers!F7="","",Tiers!F7*MAX(10,IF(Tiers!I7="",1,Tiers!I7)))),IF(Tiers!D7="flat", IF(Inputs!$B$8="annual",IF(Tiers!G7="","",Tiers!G7/12), IF(Tiers!H7="","",Tiers!H7)),"")))))) -> 90 | E10: =IF(Tiers!K7="yes","",IF(Model!F7=0,"",IF(Tiers!L7<>"public","",IF(AND(Tiers!J7<>"",25>Tiers!J7),"",IF(Tiers!D7="per_seat", IF(Inputs!$B$8="annual",IF(Tiers!E7="","",Tiers!E7*MAX(25,IF(Tiers!I7="",1,Tiers!I7))), IF(Tiers!F7="","",Tiers!F7*MAX(25,IF(Tiers!I7="",1,Tiers!I7)))),IF(Tiers!D7="flat", IF(Inputs!$B$8="annual",IF(Tiers!G7="","",Tiers!G7/12), IF(Tiers!H7="","",Tiers!H7)),"")))))) -> 225 | F10: =IF(Tiers!K7="yes","",IF(Model!F7=0,"",IF(Tiers!L7<>"public","",IF(AND(Tiers!J7<>"",50>Tiers!J7),"",IF(Tiers!D7="per_seat", IF(Inputs!$B$8="annual",IF(Tiers!E7="","",Tiers!E7*MAX(50,IF(Tiers!I7="",1,Tiers!I7))), IF(Tiers!F7="","",Tiers!F7*MAX(50,IF(Tiers!I7="",1,Tiers!I7)))),IF(Tiers!D7="flat", IF(Inputs!$B$8="annual",IF(Tiers!G7="","",Tiers!G7/12), IF(Tiers!H7="","",Tiers!H7)),"")))))) -> 450 | G10: =IF(Tiers!K7="yes","",IF(Model!F7=0,"",IF(Tiers!L7<>"public","",IF(AND(Tiers!J7<>"",100>Tiers!J7),"",IF(Tiers!D7="per_seat", IF(Inputs!$B$8="annual",IF(Tiers!E7="","",Tiers!E7*MAX(100,IF(Tiers!I7="",1,Tiers!I7))), IF(Tiers!F7="","",Tiers!F7*MAX(100,IF(Tiers!I7="",1,Tiers!I7)))),IF(Tiers!D7="flat", IF(Inputs!$B$8="annual",IF(Tiers!G7="","",Tiers!G7/12), IF(Tiers!H7="","",Tiers!H7)),"")))))) -> 900 | H10: =IF(Tiers!K7="yes","",IF(Model!F7=0,"",IF(Tiers!L7<>"public","",IF(AND(Tiers!J7<>"",250>Tiers!J7),"",IF(Tiers!D7="per_seat", IF(Inputs!$B$8="annual",IF(Tiers!E7="","",Tiers!E7*MAX(250,IF(Tiers!I7="",1,Tiers!I7))), IF(Tiers!F7="","",Tiers!F7*MAX(250,IF(Tiers!I7="",1,Tiers!I7)))),IF(Tiers!D7="flat", IF(Inputs!$B$8="annual",IF(Tiers!G7="","",Tiers!G7/12), IF(Tiers!H7="","",Tiers!H7)),"")))))) -> 2250
A11: =Tiers!A8 -> monday.com | B11: =Tiers!B8 -> Standard | C11: =IF(Tiers!K8="yes","",IF(Model!F8=0,"",IF(Tiers!L8<>"public","",IF(AND(Tiers!J8<>"",5>Tiers!J8),"",IF(Tiers!D8="per_seat", IF(Inputs!$B$8="annual",IF(Tiers!E8="","",Tiers!E8*MAX(5,IF(Tiers!I8="",1,Tiers!I8))), IF(Tiers!F8="","",Tiers!F8*MAX(5,IF(Tiers!I8="",1,Tiers!I8)))),IF(Tiers!D8="flat", IF(Inputs!$B$8="annual",IF(Tiers!G8="","",Tiers!G8/12), IF(Tiers!H8="","",Tiers!H8)),"")))))) -> 60 | D11: =IF(Tiers!K8="yes","",IF(Model!F8=0,"",IF(Tiers!L8<>"public","",IF(AND(Tiers!J8<>"",10>Tiers!J8),"",IF(Tiers!D8="per_seat", IF(Inputs!$B$8="annual",IF(Tiers!E8="","",Tiers!E8*MAX(10,IF(Tiers!I8="",1,Tiers!I8))), IF(Tiers!F8="","",Tiers!F8*MAX(10,IF(Tiers!I8="",1,Tiers!I8)))),IF(Tiers!D8="flat", IF(Inputs!$B$8="annual",IF(Tiers!G8="","",Tiers!G8/12), IF(Tiers!H8="","",Tiers!H8)),"")))))) -> 120 | E11: =IF(Tiers!K8="yes","",IF(Model!F8=0,"",IF(Tiers!L8<>"public","",IF(AND(Tiers!J8<>"",25>Tiers!J8),"",IF(Tiers!D8="per_seat", IF(Inputs!$B$8="annual",IF(Tiers!E8="","",Tiers!E8*MAX(25,IF(Tiers!I8="",1,Tiers!I8))), IF(Tiers!F8="","",Tiers!F8*MAX(25,IF(Tiers!I8="",1,Tiers!I8)))),IF(Tiers!D8="flat", IF(Inputs!$B$8="annual",IF(Tiers!G8="","",Tiers!G8/12), IF(Tiers!H8="","",Tiers!H8)),"")))))) -> 300 | F11: =IF(Tiers!K8="yes","",IF(Model!F8=0,"",IF(Tiers!L8<>"public","",IF(AND(Tiers!J8<>"",50>Tiers!J8),"",IF(Tiers!D8="per_seat", IF(Inputs!$B$8="annual",IF(Tiers!E8="","",Tiers!E8*MAX(50,IF(Tiers!I8="",1,Tiers!I8))), IF(Tiers!F8="","",Tiers!F8*MAX(50,IF(Tiers!I8="",1,Tiers!I8)))),IF(Tiers!D8="flat", IF(Inputs!$B$8="annual",IF(Tiers!G8="","",Tiers!G8/12), IF(Tiers!H8="","",Tiers!H8)),"")))))) -> 600 | G11: =IF(Tiers!K8="yes","",IF(Model!F8=0,"",IF(Tiers!L8<>"public","",IF(AND(Tiers!J8<>"",100>Tiers!J8),"",IF(Tiers!D8="per_seat", IF(Inputs!$B$8="annual",IF(Tiers!E8="","",Tiers!E8*MAX(100,IF(Tiers!I8="",1,Tiers!I8))), IF(Tiers!F8="","",Tiers!F8*MAX(100,IF(Tiers!I8="",1,Tiers!I8)))),IF(Tiers!D8="flat", IF(Inputs!$B$8="annual",IF(Tiers!G8="","",Tiers!G8/12), IF(Tiers!H8="","",Tiers!H8)),"")))))) -> 1200 | H11: =IF(Tiers!K8="yes","",IF(Model!F8=0,"",IF(Tiers!L8<>"public","",IF(AND(Tiers!J8<>"",250>Tiers!J8),"",IF(Tiers!D8="per_seat", IF(Inputs!$B$8="annual",IF(Tiers!E8="","",Tiers!E8*MAX(250,IF(Tiers!I8="",1,Tiers!I8))), IF(Tiers!F8="","",Tiers!F8*MAX(250,IF(Tiers!I8="",1,Tiers!I8)))),IF(Tiers!D8="flat", IF(Inputs!$B$8="annual",IF(Tiers!G8="","",Tiers!G8/12), IF(Tiers!H8="","",Tiers!H8)),"")))))) -> 3000
A12: =Tiers!A9 -> monday.com | B12: =Tiers!B9 -> Pro | C12: =IF(Tiers!K9="yes","",IF(Model!F9=0,"",IF(Tiers!L9<>"public","",IF(AND(Tiers!J9<>"",5>Tiers!J9),"",IF(Tiers!D9="per_seat", IF(Inputs!$B$8="annual",IF(Tiers!E9="","",Tiers!E9*MAX(5,IF(Tiers!I9="",1,Tiers!I9))), IF(Tiers!F9="","",Tiers!F9*MAX(5,IF(Tiers!I9="",1,Tiers!I9)))),IF(Tiers!D9="flat", IF(Inputs!$B$8="annual",IF(Tiers!G9="","",Tiers!G9/12), IF(Tiers!H9="","",Tiers!H9)),"")))))) -> 95 | D12: =IF(Tiers!K9="yes","",IF(Model!F9=0,"",IF(Tiers!L9<>"public","",IF(AND(Tiers!J9<>"",10>Tiers!J9),"",IF(Tiers!D9="per_seat", IF(Inputs!$B$8="annual",IF(Tiers!E9="","",Tiers!E9*MAX(10,IF(Tiers!I9="",1,Tiers!I9))), IF(Tiers!F9="","",Tiers!F9*MAX(10,IF(Tiers!I9="",1,Tiers!I9)))),IF(Tiers!D9="flat", IF(Inputs!$B$8="annual",IF(Tiers!G9="","",Tiers!G9/12), IF(Tiers!H9="","",Tiers!H9)),"")))))) -> 190 | E12: =IF(Tiers!K9="yes","",IF(Model!F9=0,"",IF(Tiers!L9<>"public","",IF(AND(Tiers!J9<>"",25>Tiers!J9),"",IF(Tiers!D9="per_seat", IF(Inputs!$B$8="annual",IF(Tiers!E9="","",Tiers!E9*MAX(25,IF(Tiers!I9="",1,Tiers!I9))), IF(Tiers!F9="","",Tiers!F9*MAX(25,IF(Tiers!I9="",1,Tiers!I9)))),IF(Tiers!D9="flat", IF(Inputs!$B$8="annual",IF(Tiers!G9="","",Tiers!G9/12), IF(Tiers!H9="","",Tiers!H9)),"")))))) -> 475 | F12: =IF(Tiers!K9="yes","",IF(Model!F9=0,"",IF(Tiers!L9<>"public","",IF(AND(Tiers!J9<>"",50>Tiers!J9),"",IF(Tiers!D9="per_seat", IF(Inputs!$B$8="annual",IF(Tiers!E9="","",Tiers!E9*MAX(50,IF(Tiers!I9="",1,Tiers!I9))), IF(Tiers!F9="","",Tiers!F9*MAX(50,IF(Tiers!I9="",1,Tiers!I9)))),IF(Tiers!D9="flat", IF(Inputs!$B$8="annual",IF(Tiers!G9="","",Tiers!G9/12), IF(Tiers!H9="","",Tiers!H9)),"")))))) -> 950 | G12: =IF(Tiers!K9="yes","",IF(Model!F9=0,"",IF(Tiers!L9<>"public","",IF(AND(Tiers!J9<>"",100>Tiers!J9),"",IF(Tiers!D9="per_seat", IF(Inputs!$B$8="annual",IF(Tiers!E9="","",Tiers!E9*MAX(100,IF(Tiers!I9="",1,Tiers!I9))), IF(Tiers!F9="","",Tiers!F9*MAX(100,IF(Tiers!I9="",1,Tiers!I9)))),IF(Tiers!D9="flat", IF(Inputs!$B$8="annual",IF(Tiers!G9="","",Tiers!G9/12), IF(Tiers!H9="","",Tiers!H9)),"")))))) -> 1900 | H12: =IF(Tiers!K9="yes","",IF(Model!F9=0,"",IF(Tiers!L9<>"public","",IF(AND(Tiers!J9<>"",250>Tiers!J9),"",IF(Tiers!D9="per_seat", IF(Inputs!$B$8="annual",IF(Tiers!E9="","",Tiers!E9*MAX(250,IF(Tiers!I9="",1,Tiers!I9))), IF(Tiers!F9="","",Tiers!F9*MAX(250,IF(Tiers!I9="",1,Tiers!I9)))),IF(Tiers!D9="flat", IF(Inputs!$B$8="annual",IF(Tiers!G9="","",Tiers!G9/12), IF(Tiers!H9="","",Tiers!H9)),"")))))) -> 4750
A13: =Tiers!A10 -> monday.com | B13: =Tiers!B10 -> Enterprise | C13: =IF(Tiers!K10="yes","",IF(Model!F10=0,"",IF(Tiers!L10<>"public","",IF(AND(Tiers!J10<>"",5>Tiers!J10),"",IF(Tiers!D10="per_seat", IF(Inputs!$B$8="annual",IF(Tiers!E10="","",Tiers!E10*MAX(5,IF(Tiers!I10="",1,Tiers!I10))), IF(Tiers!F10="","",Tiers!F10*MAX(5,IF(Tiers!I10="",1,Tiers!I10)))),IF(Tiers!D10="flat", IF(Inputs!$B$8="annual",IF(Tiers!G10="","",Tiers!G10/12), IF(Tiers!H10="","",Tiers!H10)),"")))))) | D13: =IF(Tiers!K10="yes","",IF(Model!F10=0,"",IF(Tiers!L10<>"public","",IF(AND(Tiers!J10<>"",10>Tiers!J10),"",IF(Tiers!D10="per_seat", IF(Inputs!$B$8="annual",IF(Tiers!E10="","",Tiers!E10*MAX(10,IF(Tiers!I10="",1,Tiers!I10))), IF(Tiers!F10="","",Tiers!F10*MAX(10,IF(Tiers!I10="",1,Tiers!I10)))),IF(Tiers!D10="flat", IF(Inputs!$B$8="annual",IF(Tiers!G10="","",Tiers!G10/12), IF(Tiers!H10="","",Tiers!H10)),"")))))) | E13: =IF(Tiers!K10="yes","",IF(Model!F10=0,"",IF(Tiers!L10<>"public","",IF(AND(Tiers!J10<>"",25>Tiers!J10),"",IF(Tiers!D10="per_seat", IF(Inputs!$B$8="annual",IF(Tiers!E10="","",Tiers!E10*MAX(25,IF(Tiers!I10="",1,Tiers!I10))), IF(Tiers!F10="","",Tiers!F10*MAX(25,IF(Tiers!I10="",1,Tiers!I10)))),IF(Tiers!D10="flat", IF(Inputs!$B$8="annual",IF(Tiers!G10="","",Tiers!G10/12), IF(Tiers!H10="","",Tiers!H10)),"")))))) | F13: =IF(Tiers!K10="yes","",IF(Model!F10=0,"",IF(Tiers!L10<>"public","",IF(AND(Tiers!J10<>"",50>Tiers!J10),"",IF(Tiers!D10="per_seat", IF(Inputs!$B$8="annual",IF(Tiers!E10="","",Tiers!E10*MAX(50,IF(Tiers!I10="",1,Tiers!I10))), IF(Tiers!F10="","",Tiers!F10*MAX(50,IF(Tiers!I10="",1,Tiers!I10)))),IF(Tiers!D10="flat", IF(Inputs!$B$8="annual",IF(Tiers!G10="","",Tiers!G10/12), IF(Tiers!H10="","",Tiers!H10)),"")))))) | G13: =IF(Tiers!K10="yes","",IF(Model!F10=0,"",IF(Tiers!L10<>"public","",IF(AND(Tiers!J10<>"",100>Tiers!J10),"",IF(Tiers!D10="per_seat", IF(Inputs!$B$8="annual",IF(Tiers!E10="","",Tiers!E10*MAX(100,IF(Tiers!I10="",1,Tiers!I10))), IF(Tiers!F10="","",Tiers!F10*MAX(100,IF(Tiers!I10="",1,Tiers!I10)))),IF(Tiers!D10="flat", IF(Inputs!$B$8="annual",IF(Tiers!G10="","",Tiers!G10/12), IF(Tiers!H10="","",Tiers!H10)),"")))))) | H13: =IF(Tiers!K10="yes","",IF(Model!F10=0,"",IF(Tiers!L10<>"public","",IF(AND(Tiers!J10<>"",250>Tiers!J10),"",IF(Tiers!D10="per_seat", IF(Inputs!$B$8="annual",IF(Tiers!E10="","",Tiers!E10*MAX(250,IF(Tiers!I10="",1,Tiers!I10))), IF(Tiers!F10="","",Tiers!F10*MAX(250,IF(Tiers!I10="",1,Tiers!I10)))),IF(Tiers!D10="flat", IF(Inputs!$B$8="annual",IF(Tiers!G10="","",Tiers!G10/12), IF(Tiers!H10="","",Tiers!H10)),""))))))
A14: =Tiers!A11 -> ClickUp | B14: =Tiers!B11 -> Free Forever | C14: =IF(Tiers!K11="yes","",IF(Model!F11=0,"",IF(Tiers!L11<>"public","",IF(AND(Tiers!J11<>"",5>Tiers!J11),"",IF(Tiers!D11="per_seat", IF(Inputs!$B$8="annual",IF(Tiers!E11="","",Tiers!E11*MAX(5,IF(Tiers!I11="",1,Tiers!I11))), IF(Tiers!F11="","",Tiers!F11*MAX(5,IF(Tiers!I11="",1,Tiers!I11)))),IF(Tiers!D11="flat", IF(Inputs!$B$8="annual",IF(Tiers!G11="","",Tiers!G11/12), IF(Tiers!H11="","",Tiers!H11)),"")))))) | D14: =IF(Tiers!K11="yes","",IF(Model!F11=0,"",IF(Tiers!L11<>"public","",IF(AND(Tiers!J11<>"",10>Tiers!J11),"",IF(Tiers!D11="per_seat", IF(Inputs!$B$8="annual",IF(Tiers!E11="","",Tiers!E11*MAX(10,IF(Tiers!I11="",1,Tiers!I11))), IF(Tiers!F11="","",Tiers!F11*MAX(10,IF(Tiers!I11="",1,Tiers!I11)))),IF(Tiers!D11="flat", IF(Inputs!$B$8="annual",IF(Tiers!G11="","",Tiers!G11/12), IF(Tiers!H11="","",Tiers!H11)),"")))))) | E14: =IF(Tiers!K11="yes","",IF(Model!F11=0,"",IF(Tiers!L11<>"public","",IF(AND(Tiers!J11<>"",25>Tiers!J11),"",IF(Tiers!D11="per_seat", IF(Inputs!$B$8="annual",IF(Tiers!E11="","",Tiers!E11*MAX(25,IF(Tiers!I11="",1,Tiers!I11))), IF(Tiers!F11="","",Tiers!F11*MAX(25,IF(Tiers!I11="",1,Tiers!I11)))),IF(Tiers!D11="flat", IF(Inputs!$B$8="annual",IF(Tiers!G11="","",Tiers!G11/12), IF(Tiers!H11="","",Tiers!H11)),"")))))) | F14: =IF(Tiers!K11="yes","",IF(Model!F11=0,"",IF(Tiers!L11<>"public","",IF(AND(Tiers!J11<>"",50>Tiers!J11),"",IF(Tiers!D11="per_seat", IF(Inputs!$B$8="annual",IF(Tiers!E11="","",Tiers!E11*MAX(50,IF(Tiers!I11="",1,Tiers!I11))), IF(Tiers!F11="","",Tiers!F11*MAX(50,IF(Tiers!I11="",1,Tiers!I11)))),IF(Tiers!D11="flat", IF(Inputs!$B$8="annual",IF(Tiers!G11="","",Tiers!G11/12), IF(Tiers!H11="","",Tiers!H11)),"")))))) | G14: =IF(Tiers!K11="yes","",IF(Model!F11=0,"",IF(Tiers!L11<>"public","",IF(AND(Tiers!J11<>"",100>Tiers!J11),"",IF(Tiers!D11="per_seat", IF(Inputs!$B$8="annual",IF(Tiers!E11="","",Tiers!E11*MAX(100,IF(Tiers!I11="",1,Tiers!I11))), IF(Tiers!F11="","",Tiers!F11*MAX(100,IF(Tiers!I11="",1,Tiers!I11)))),IF(Tiers!D11="flat", IF(Inputs!$B$8="annual",IF(Tiers!G11="","",Tiers!G11/12), IF(Tiers!H11="","",Tiers!H11)),"")))))) | H14: =IF(Tiers!K11="yes","",IF(Model!F11=0,"",IF(Tiers!L11<>"public","",IF(AND(Tiers!J11<>"",250>Tiers!J11),"",IF(Tiers!D11="per_seat", IF(Inputs!$B$8="annual",IF(Tiers!E11="","",Tiers!E11*MAX(250,IF(Tiers!I11="",1,Tiers!I11))), IF(Tiers!F11="","",Tiers!F11*MAX(250,IF(Tiers!I11="",1,Tiers!I11)))),IF(Tiers!D11="flat", IF(Inputs!$B$8="annual",IF(Tiers!G11="","",Tiers!G11/12), IF(Tiers!H11="","",Tiers!H11)),""))))))
A15: =Tiers!A12 -> ClickUp | B15: =Tiers!B12 -> Unlimited | C15: =IF(Tiers!K12="yes","",IF(Model!F12=0,"",IF(Tiers!L12<>"public","",IF(AND(Tiers!J12<>"",5>Tiers!J12),"",IF(Tiers!D12="per_seat", IF(Inputs!$B$8="annual",IF(Tiers!E12="","",Tiers!E12*MAX(5,IF(Tiers!I12="",1,Tiers!I12))), IF(Tiers!F12="","",Tiers!F12*MAX(5,IF(Tiers!I12="",1,Tiers!I12)))),IF(Tiers!D12="flat", IF(Inputs!$B$8="annual",IF(Tiers!G12="","",Tiers!G12/12), IF(Tiers!H12="","",Tiers!H12)),"")))))) -> 35 | D15: =IF(Tiers!K12="yes","",IF(Model!F12=0,"",IF(Tiers!L12<>"public","",IF(AND(Tiers!J12<>"",10>Tiers!J12),"",IF(Tiers!D12="per_seat", IF(Inputs!$B$8="annual",IF(Tiers!E12="","",Tiers!E12*MAX(10,IF(Tiers!I12="",1,Tiers!I12))), IF(Tiers!F12="","",Tiers!F12*MAX(10,IF(Tiers!I12="",1,Tiers!I12)))),IF(Tiers!D12="flat", IF(Inputs!$B$8="annual",IF(Tiers!G12="","",Tiers!G12/12), IF(Tiers!H12="","",Tiers!H12)),"")))))) -> 70 | E15: =IF(Tiers!K12="yes","",IF(Model!F12=0,"",IF(Tiers!L12<>"public","",IF(AND(Tiers!J12<>"",25>Tiers!J12),"",IF(Tiers!D12="per_seat", IF(Inputs!$B$8="annual",IF(Tiers!E12="","",Tiers!E12*MAX(25,IF(Tiers!I12="",1,Tiers!I12))), IF(Tiers!F12="","",Tiers!F12*MAX(25,IF(Tiers!I12="",1,Tiers!I12)))),IF(Tiers!D12="flat", IF(Inputs!$B$8="annual",IF(Tiers!G12="","",Tiers!G12/12), IF(Tiers!H12="","",Tiers!H12)),"")))))) -> 175 | F15: =IF(Tiers!K12="yes","",IF(Model!F12=0,"",IF(Tiers!L12<>"public","",IF(AND(Tiers!J12<>"",50>Tiers!J12),"",IF(Tiers!D12="per_seat", IF(Inputs!$B$8="annual",IF(Tiers!E12="","",Tiers!E12*MAX(50,IF(Tiers!I12="",1,Tiers!I12))), IF(Tiers!F12="","",Tiers!F12*MAX(50,IF(Tiers!I12="",1,Tiers!I12)))),IF(Tiers!D12="flat", IF(Inputs!$B$8="annual",IF(Tiers!G12="","",Tiers!G12/12), IF(Tiers!H12="","",Tiers!H12)),"")))))) -> 350 | G15: =IF(Tiers!K12="yes","",IF(Model!F12=0,"",IF(Tiers!L12<>"public","",IF(AND(Tiers!J12<>"",100>Tiers!J12),"",IF(Tiers!D12="per_seat", IF(Inputs!$B$8="annual",IF(Tiers!E12="","",Tiers!E12*MAX(100,IF(Tiers!I12="",1,Tiers!I12))), IF(Tiers!F12="","",Tiers!F12*MAX(100,IF(Tiers!I12="",1,Tiers!I12)))),IF(Tiers!D12="flat", IF(Inputs!$B$8="annual",IF(Tiers!G12="","",Tiers!G12/12), IF(Tiers!H12="","",Tiers!H12)),"")))))) -> 700 | H15: =IF(Tiers!K12="yes","",IF(Model!F12=0,"",IF(Tiers!L12<>"public","",IF(AND(Tiers!J12<>"",250>Tiers!J12),"",IF(Tiers!D12="per_seat", IF(Inputs!$B$8="annual",IF(Tiers!E12="","",Tiers!E12*MAX(250,IF(Tiers!I12="",1,Tiers!I12))), IF(Tiers!F12="","",Tiers!F12*MAX(250,IF(Tiers!I12="",1,Tiers!I12)))),IF(Tiers!D12="flat", IF(Inputs!$B$8="annual",IF(Tiers!G12="","",Tiers!G12/12), IF(Tiers!H12="","",Tiers!H12)),"")))))) -> 1750
A16: =Tiers!A13 -> ClickUp | B16: =Tiers!B13 -> Business | C16: =IF(Tiers!K13="yes","",IF(Model!F13=0,"",IF(Tiers!L13<>"public","",IF(AND(Tiers!J13<>"",5>Tiers!J13),"",IF(Tiers!D13="per_seat", IF(Inputs!$B$8="annual",IF(Tiers!E13="","",Tiers!E13*MAX(5,IF(Tiers!I13="",1,Tiers!I13))), IF(Tiers!F13="","",Tiers!F13*MAX(5,IF(Tiers!I13="",1,Tiers!I13)))),IF(Tiers!D13="flat", IF(Inputs!$B$8="annual",IF(Tiers!G13="","",Tiers!G13/12), IF(Tiers!H13="","",Tiers!H13)),"")))))) -> 60 | D16: =IF(Tiers!K13="yes","",IF(Model!F13=0,"",IF(Tiers!L13<>"public","",IF(AND(Tiers!J13<>"",10>Tiers!J13),"",IF(Tiers!D13="per_seat", IF(Inputs!$B$8="annual",IF(Tiers!E13="","",Tiers!E13*MAX(10,IF(Tiers!I13="",1,Tiers!I13))), IF(Tiers!F13="","",Tiers!F13*MAX(10,IF(Tiers!I13="",1,Tiers!I13)))),IF(Tiers!D13="flat", IF(Inputs!$B$8="annual",IF(Tiers!G13="","",Tiers!G13/12), IF(Tiers!H13="","",Tiers!H13)),"")))))) -> 120 | E16: =IF(Tiers!K13="yes","",IF(Model!F13=0,"",IF(Tiers!L13<>"public","",IF(AND(Tiers!J13<>"",25>Tiers!J13),"",IF(Tiers!D13="per_seat", IF(Inputs!$B$8="annual",IF(Tiers!E13="","",Tiers!E13*MAX(25,IF(Tiers!I13="",1,Tiers!I13))), IF(Tiers!F13="","",Tiers!F13*MAX(25,IF(Tiers!I13="",1,Tiers!I13)))),IF(Tiers!D13="flat", IF(Inputs!$B$8="annual",IF(Tiers!G13="","",Tiers!G13/12), IF(Tiers!H13="","",Tiers!H13)),"")))))) -> 300 | F16: =IF(Tiers!K13="yes","",IF(Model!F13=0,"",IF(Tiers!L13<>"public","",IF(AND(Tiers!J13<>"",50>Tiers!J13),"",IF(Tiers!D13="per_seat", IF(Inputs!$B$8="annual",IF(Tiers!E13="","",Tiers!E13*MAX(50,IF(Tiers!I13="",1,Tiers!I13))), IF(Tiers!F13="","",Tiers!F13*MAX(50,IF(Tiers!I13="",1,Tiers!I13)))),IF(Tiers!D13="flat", IF(Inputs!$B$8="annual",IF(Tiers!G13="","",Tiers!G13/12), IF(Tiers!H13="","",Tiers!H13)),"")))))) -> 600 | G16: =IF(Tiers!K13="yes","",IF(Model!F13=0,"",IF(Tiers!L13<>"public","",IF(AND(Tiers!J13<>"",100>Tiers!J13),"",IF(Tiers!D13="per_seat", IF(Inputs!$B$8="annual",IF(Tiers!E13="","",Tiers!E13*MAX(100,IF(Tiers!I13="",1,Tiers!I13))), IF(Tiers!F13="","",Tiers!F13*MAX(100,IF(Tiers!I13="",1,Tiers!I13)))),IF(Tiers!D13="flat", IF(Inputs!$B$8="annual",IF(Tiers!G13="","",Tiers!G13/12), IF(Tiers!H13="","",Tiers!H13)),"")))))) -> 1200 | H16: =IF(Tiers!K13="yes","",IF(Model!F13=0,"",IF(Tiers!L13<>"public","",IF(AND(Tiers!J13<>"",250>Tiers!J13),"",IF(Tiers!D13="per_seat", IF(Inputs!$B$8="annual",IF(Tiers!E13="","",Tiers!E13*MAX(250,IF(Tiers!I13="",1,Tiers!I13))), IF(Tiers!F13="","",Tiers!F13*MAX(250,IF(Tiers!I13="",1,Tiers!I13)))),IF(Tiers!D13="flat", IF(Inputs!$B$8="annual",IF(Tiers!G13="","",Tiers!G13/12), IF(Tiers!H13="","",Tiers!H13)),"")))))) -> 3000
... A66: =Tiers!A63 -> Runrun.it | B66: =Tiers!B63 -> Enterprise | C66: =IF(Tiers!K63="yes","",IF(Model!F63=0,"",IF(Tiers!L63<>"public","",IF(AND(Tiers!J63<>"",5>Tiers!J63),"",IF(Tiers!D63="per_seat", IF(Inputs!$B$8="annual",IF(Tiers!E63="","",Tiers!E63*MAX(5,IF(Tiers!I63="",1,Tiers!I63))), IF(Tiers!F63="","",Tiers!F63*MAX(5,IF(Tiers!I63="",1,Tiers!I63)))),IF(Tiers!D63="flat", IF(Inputs!$B$8="annual",IF(Tiers!G63="","",Tiers!G63/12), IF(Tiers!H63="","",Tiers!H63)),"")))))) -> 130 | D66: =IF(Tiers!K63="yes","",IF(Model!F63=0,"",IF(Tiers!L63<>"public","",IF(AND(Tiers!J63<>"",10>Tiers!J63),"",IF(Tiers!D63="per_seat", IF(Inputs!$B$8="annual",IF(Tiers!E63="","",Tiers!E63*MAX(10,IF(Tiers!I63="",1,Tiers!I63))), IF(Tiers!F63="","",Tiers!F63*MAX(10,IF(Tiers!I63="",1,Tiers!I63)))),IF(Tiers!D63="flat", IF(Inputs!$B$8="annual",IF(Tiers!G63="","",Tiers!G63/12), IF(Tiers!H63="","",Tiers!H63)),"")))))) -> 260 | E66: =IF(Tiers!K63="yes","",IF(Model!F63=0,"",IF(Tiers!L63<>"public","",IF(AND(Tiers!J63<>"",25>Tiers!J63),"",IF(Tiers!D63="per_seat", IF(Inputs!$B$8="annual",IF(Tiers!E63="","",Tiers!E63*MAX(25,IF(Tiers!I63="",1,Tiers!I63))), IF(Tiers!F63="","",Tiers!F63*MAX(25,IF(Tiers!I63="",1,Tiers!I63)))),IF(Tiers!D63="flat", IF(Inputs!$B$8="annual",IF(Tiers!G63="","",Tiers!G63/12), IF(Tiers!H63="","",Tiers!H63)),"")))))) -> 650 | F66: =IF(Tiers!K63="yes","",IF(Model!F63=0,"",IF(Tiers!L63<>"public","",IF(AND(Tiers!J63<>"",50>Tiers!J63),"",IF(Tiers!D63="per_seat", IF(Inputs!$B$8="annual",IF(Tiers!E63="","",Tiers!E63*MAX(50,IF(Tiers!I63="",1,Tiers!I63))), IF(Tiers!F63="","",Tiers!F63*MAX(50,IF(Tiers!I63="",1,Tiers!I63)))),IF(Tiers!D63="flat", IF(Inputs!$B$8="annual",IF(Tiers!G63="","",Tiers!G63/12), IF(Tiers!H63="","",Tiers!H63)),"")))))) -> 1300 | G66: =IF(Tiers!K63="yes","",IF(Model!F63=0,"",IF(Tiers!L63<>"public","",IF(AND(Tiers!J63<>"",100>Tiers!J63),"",IF(Tiers!D63="per_seat", IF(Inputs!$B$8="annual",IF(Tiers!E63="","",Tiers!E63*MAX(100,IF(Tiers!I63="",1,Tiers!I63))), IF(Tiers!F63="","",Tiers!F63*MAX(100,IF(Tiers!I63="",1,Tiers!I63)))),IF(Tiers!D63="flat", IF(Inputs!$B$8="annual",IF(Tiers!G63="","",Tiers!G63/12), IF(Tiers!H63="","",Tiers!H63)),"")))))) -> 2600 | H66: =IF(Tiers!K63="yes","",IF(Model!F63=0,"",IF(Tiers!L63<>"public","",IF(AND(Tiers!J63<>"",250>Tiers!J63),"",IF(Tiers!D63="per_seat", IF(Inputs!$B$8="annual",IF(Tiers!E63="","",Tiers!E63*MAX(250,IF(Tiers!I63="",1,Tiers!I63))), IF(Tiers!F63="","",Tiers!F63*MAX(250,IF(Tiers!I63="",1,Tiers!I63)))),IF(Tiers!D63="flat", IF(Inputs!$B$8="annual",IF(Tiers!G63="","",Tiers!G63/12), IF(Tiers!H63="","",Tiers!H63)),"")))))) -> 6500

Sheet Compare
A1: Cheapest qualifying tier, by team size
A2: Blank means no tier from that vendor qualifies at that size: either every tier is capped below it, or none meets the requirements set on Inputs, or the tier that would is contact-sales.
A4: Vendor | B4: 5 seats | C4: 10 seats | D4: 25 seats | E4: 50 seats | F4: 100 seats | G4: 250 seats | H4: $ per seat at 100
A5: Smartsheet | B5: =IF(IFERROR(_xlfn.MINIFS(Grid!$C$5:$C$66,Grid!$A$5:$A$66,$A5),0)=0,"",_xlfn.MINIFS(Grid!$C$5:$C$66,Grid!$A$5:$A$66,$A5)) -> 45 | C5: =IF(IFERROR(_xlfn.MINIFS(Grid!$D$5:$D$66,Grid!$A$5:$A$66,$A5),0)=0,"",_xlfn.MINIFS(Grid!$D$5:$D$66,Grid!$A$5:$A$66,$A5)) -> 90 | D5: =IF(IFERROR(_xlfn.MINIFS(Grid!$E$5:$E$66,Grid!$A$5:$A$66,$A5),0)=0,"",_xlfn.MINIFS(Grid!$E$5:$E$66,Grid!$A$5:$A$66,$A5)) -> 475 | E5: =IF(IFERROR(_xlfn.MINIFS(Grid!$F$5:$F$66,Grid!$A$5:$A$66,$A5),0)=0,"",_xlfn.MINIFS(Grid!$F$5:$F$66,Grid!$A$5:$A$66,$A5)) -> 950 | F5: =IF(IFERROR(_xlfn.MINIFS(Grid!$G$5:$G$66,Grid!$A$5:$A$66,$A5),0)=0,"",_xlfn.MINIFS(Grid!$G$5:$G$66,Grid!$A$5:$A$66,$A5)) -> 1900 | G5: =IF(IFERROR(_xlfn.MINIFS(Grid!$H$5:$H$66,Grid!$A$5:$A$66,$A5),0)=0,"",_xlfn.MINIFS(Grid!$H$5:$H$66,Grid!$A$5:$A$66,$A5)) -> 4750 | H5: =IF(F5="","",F5/100) -> 19
A6: monday.com | B6: =IF(IFERROR(_xlfn.MINIFS(Grid!$C$5:$C$66,Grid!$A$5:$A$66,$A6),0)=0,"",_xlfn.MINIFS(Grid!$C$5:$C$66,Grid!$A$5:$A$66,$A6)) -> 45 | C6: =IF(IFERROR(_xlfn.MINIFS(Grid!$D$5:$D$66,Grid!$A$5:$A$66,$A6),0)=0,"",_xlfn.MINIFS(Grid!$D$5:$D$66,Grid!$A$5:$A$66,$A6)) -> 90 | D6: =IF(IFERROR(_xlfn.MINIFS(Grid!$E$5:$E$66,Grid!$A$5:$A$66,$A6),0)=0,"",_xlfn.MINIFS(Grid!$E$5:$E$66,Grid!$A$5:$A$66,$A6)) -> 225 | E6: =IF(IFERROR(_xlfn.MINIFS(Grid!$F$5:$F$66,Grid!$A$5:$A$66,$A6),0)=0,"",_xlfn.MINIFS(Grid!$F$5:$F$66,Grid!$A$5:$A$66,$A6)) -> 450 | F6: =IF(IFERROR(_xlfn.MINIFS(Grid!$G$5:$G$66,Grid!$A$5:$A$66,$A6),0)=0,"",_xlfn.MINIFS(Grid!$G$5:$G$66,Grid!$A$5:$A$66,$A6)) -> 900 | G6: =IF(IFERROR(_xlfn.MINIFS(Grid!$H$5:$H$66,Grid!$A$5:$A$66,$A6),0)=0,"",_xlfn.MINIFS(Grid!$H$5:$H$66,Grid!$A$5:$A$66,$A6)) -> 2250 | H6: =IF(F6="","",F6/100) -> 9
